Workbook
Name lst_Units: 'Lists'!$B$6:$B$30
Name lst_ExpCat: 'Lists'!$F$6:$F$35
Name lst_Pay: 'Lists'!$J$6:$J$20
Name lst_MenuCat: 'Lists'!$L$6:$L$20
Name lst_Waste: 'Lists'!$N$6:$N$20
Name lst_Period: 'Lists'!$P$6:$P$18
Name cfg_Business: 'Settings'!$C$6
Name cfg_Symbol: 'Settings'!$C$18
Name cfg_Currency: 'Settings'!$C$19
Name cfg_Year: 'Settings'!$C$21
Name cfg_Start: 'Settings'!$C$22
Name cfg_End: 'Settings'!$C$23
Name cfg_Months: 'Settings'!$C$24
Name cfg_PeriodLabel: 'Settings'!$C$25
Name cfg_CountDate: 'Settings'!$C$26
Name cfg_LaborRate: 'Settings'!$C$27
Name cfg_TargetMargin: 'Settings'!$C$28
Name cfg_FoodCostTarget: 'Settings'!$C$29
Name cfg_Round: 'Settings'!$C$30
Name ps_rev: 'Monthly Report'!$G$25
Name ps_items: 'Monthly Report'!$G$26
Name ps_cogs: 'Monthly Report'!$G$27
Name ps_gp: 'Monthly Report'!$G$28
Name ps_gm: 'Monthly Report'!$G$29
Name ps_waste: 'Monthly Report'!$G$30
Name ps_fixed: 'Monthly Report'!$G$31
Name ps_labor: 'Monthly Report'!$G$32
Name ps_event: 'Monthly Report'!$G$33
Name ps_var: 'Monthly Report'!$G$34
Name ps_opex: 'Monthly Report'!$G$35
Name ps_net: 'Monthly Report'!$G$36
Name ps_nm: 'Monthly Report'!$G$37
Name ps_lines: 'Monthly Report'!$G$38
Name ps_avgp: 'Monthly Report'!$G$39
Name ps_active: 'Monthly Report'!$G$40
Name ps_avgopex: 'Monthly Report'!$G$41
Name ps_berev: 'Monthly Report'!$G$42
Name ps_beprog: 'Monthly Report'!$G$43
Name ps_stock: 'Monthly Report'!$G$44
Name ps_unclassified: 'Monthly Report'!$G$45
Name be_Revenue: 'Break-Even'!$H$27
Name be_Items: 'Break-Even'!$H$20

Sheet Start Here
B2: Food Truck Profit & Pricing System PRO
B3: by NoviraNest · Version 1.0.0 · Works in Microsoft Excel and Google Sheets · No macros
B6: THIS IS YOUR CLEAN TEMPLATE. Every log is empty and ready for your data. Want to see it filled in first? Open the SAMPLE file.
B8: Quick setup (about 30 minutes, once)
B9: 1 | C9: Settings | D9: Business name, currency (USD or GBP), reporting year, labour rate, target margin and food cost %.
B10: 2 | C10: Inventory | D10: List your ingredients: the unit you count them in, pack size and pack price. Cost per unit is automatic.
B11: 3 | C11: Recipe Builder | D11: First add menu item names on Menu Pricing, then here list what goes into ONE serving. Units convert automatically.
B12: 4 | C12: Menu Pricing | D12: Add packaging, prep minutes and your menu price. See the suggested price, margin, markup and status.
B13: 5 | C13: Break-Even | D13: Type your monthly fixed costs once. The Dashboard then shows your break-even progress.
B14: 6 | C14: Daily / weekly | D14: Log sales on the Sales Log, costs on Expenses and thrown-away food on the Waste Log. Then open the Dashboard.
B16: What the colours mean
C17: Cream cell, blue text | D17: Type here. These are the only cells you need to fill in.
C18: Grey cell | D18: Automatic formula. Please don't type over it.
C19: Red / pink | D19: Something needs your attention (loss-making item, unit mismatch, bad row).
C20: Blue box | D20: Instructions and explanations.
B22: Sheet directory
C23: › Dashboard | D23: KPI cards, monthly chart, expense breakdown, best sellers, most profitable items, alerts.
C24: › Settings | D24: Your business settings. Everything reads from here.
C25: › Menu Pricing | D25: Smart pricing: cost per serving, suggested price, margin vs markup, food cost %, status, sales by item.
C26: › Recipe Builder | D26: Ingredients per serving with automatic unit conversion and mismatch protection.
C27: › Inventory | D27: Ingredient prices, estimated stock on hand, stock value and reorder alerts.
C28: › Waste Log | D28: Food thrown away, valued automatically.
C29: › Sales Log | D29: Every sale: revenue, cost and gross profit calculated for you (3,000 rows).
C30: › Expenses | D30: Every business cost with a category (1,500 rows).
C31: › Monthly Report | D31: Profit & loss by month and the selected-period summary.
C32: › Break-Even | D32: Break-even items and revenue, target profit, chart.
C33: › Event Predictor | D33: Forecast an event (worst / base / best), then compare with actual results.
C34: › Scenario Simulator | D34: What-if: ingredient inflation, price changes, busy/slow season, wage rises.
C35: › Lists | D35: Units, expense categories and dropdown lists you can extend.
B37: How the numbers work
C38: Revenue | D38: Items sold x price charged (menu price unless you typed a different price on the Sales Log).
C39: COGS | D39: Cost of goods sold = items sold x (ingredients + packaging + other variable cost per serving). Labour is NOT in COGS.
C40: Gross profit | D40: Revenue - COGS. Gross margin = gross profit / revenue.
C41: Net profit | D41: Gross profit - waste - operating expenses (fixed, labour, event fees, other variable). Before income tax.
C42: Not double counted | D42: Ingredient purchases and owner's draw can be logged on Expenses but are excluded from profit: the food you used is already in COGS. Prep labour on Menu Pricing is a pricing allowance only; real wages go in Expenses.
C43: Margin vs markup | D43: Margin = profit / PRICE. Markup = profit / COST. Cost 4.00, price 10.00 -> margin 60%, markup 150%.
C44: Food cost % | D44: Ingredient cost / menu price.
C45: Break-even | D45: Monthly fixed costs / contribution per item (price - item cost - % fees).
C46: Currency | D46: USD or GBP changes symbols only. Amounts are never converted with an exchange rate.
C47: Forecasts | D47: Event Predictor and Scenario Simulator are estimates. They never change your actual figures.
...

Sheet Dashboard
B2: =cfg_Business | M2: NoviraNest
B3: ="Executive Dashboard · "&cfg_PeriodLabel&" · "&cfg_Currency | M3: Food Truck Profit & Pricing PRO
B4: › Start Here | D4: › Settings | F4: › Menu Pricing | H4: › Sales Log | J4: › Expenses | L4: › Break-Even | N4: › Event Predictor | P4: › Scenario Simulator
B6: =IF(ps_lines=0,"No sales recorded for "&cfg_PeriodLabel&" yet. Start with Settings, then add your menu, and log sales on the Sales Log - this dashboard fills in automatically.",IF(ISNUMBER(SEARCH("DEMO",cfg_Business)),"SAMPLE DATA: fictional demo business for illustration only - not real results. Use the TEMPLATE file for your own business.",""))
B8: TOTAL REVENUE | F8: GROSS PROFIT | J8: NET PROFIT | N8: NET PROFIT MARGIN
B9: =IF(N(ps_rev)<0,"-","")&cfg_Symbol&TEXT(ABS(N(ps_rev)),"#,##0") | F9: =IF(N(ps_gp)<0,"-","")&cfg_Symbol&TEXT(ABS(N(ps_gp)),"#,##0") | J9: =IF(N(ps_net)<0,"-","")&cfg_Symbol&TEXT(ABS(N(ps_net)),"#,##0") | N9: =IF(ps_nm="","-",TEXT(ps_nm,"0.0%"))
B10: =TEXT(ps_items,"#,##0")&" items sold · avg "&cfg_Symbol&TEXT(N(ps_avgp),"0.00")&" per item" | F10: =IF(ps_gm="","Gross margin: -","Gross margin: "&TEXT(ps_gm,"0.0%"))&" · after food & packaging" | J10: ="After waste and all operating expenses (before tax)" | N10: ="Net profit / revenue"
B12: MONTHLY OPERATING EXPENSES | F12: COST OF GOODS SOLD | J12: WASTE | N12: BREAK-EVEN PROGRESS
B13: =IF(N(ps_avgopex)<0,"-","")&cfg_Symbol&TEXT(ABS(N(ps_avgopex)),"#,##0") | F13: =IF(N(ps_cogs)<0,"-","")&cfg_Symbol&TEXT(ABS(N(ps_cogs)),"#,##0") | J13: =IF(N(ps_waste)<0,"-","")&cfg_Symbol&TEXT(ABS(N(ps_waste)),"#,##0") | N13: =IF(ps_beprog="","Set up",TEXT(ps_beprog,"0%"))
B14: =IF(cfg_Months=1,"This month","Average of "&ps_active&" active month(s)")&" · total "&cfg_Symbol&TEXT(ps_opex,"#,##0") | F14: =IF(N(ps_rev)=0,"Food + packaging + other variable","= "&TEXT(ps_cogs/ps_rev,"0.0%")&" of revenue (food + packaging)") | J14: =IF(N(ps_rev)=0,"Logged on the Waste Log",TEXT(ps_waste/ps_rev,"0.0%")&" of revenue · from the Waste Log") | N14: =IF(ps_beprog="","Enter fixed costs on Break-Even",REPT("█",MIN(10,ROUND(ps_beprog*10,0)))&REPT("░",MAX(0,10-ROUND(ps_beprog*10,0)))&" of "&cfg_Symbol&TEXT(ps_berev,"#,##0"))
B16: ="MONTHLY PERFORMANCE · "&cfg_Year | J16: ="WHERE THE MONEY GOES · "&cfg_PeriodLabel
B33: ="BEST SELLERS · "&cfg_PeriodLabel | J33: ="MOST PROFITABLE ITEMS · "&cfg_PeriodLabel
B34: # Menu item | F34: Items sold | H34: ="Revenue ("&cfg_Symbol&")" | J34: # Menu item | N34: ="Gross profit ("&cfg_Symbol&")" | P34: Status
B35: =IFERROR(IF(AND(LARGE('Menu Pricing'!$Z$7:$Z$56,1)>=1,INDEX('Menu Pricing'!$V$7:$V$56,MATCH(LARGE('Menu Pricing'!$Z$7:$Z$56,1),'Menu Pricing'!$Z$7:$Z$56,0))>0),"1. "&INDEX('Menu Pricing'!$B$7:$B$56,MATCH(LARGE('Menu Pricing'!$Z$7:$Z$56,1),'Menu Pricing'!$Z$7:$Z$56,0)),IF(1=1,"No sales in this period yet","")),"") | F35: =IFERROR(IF(AND(LARGE('Menu Pricing'!$Z$7:$Z$56,1)>=1,INDEX('Menu Pricing'!$V$7:$V$56,MATCH(LARGE('Menu Pricing'!$Z$7:$Z$56,1),'Menu Pricing'!$Z$7:$Z$56,0))>0),INDEX('Menu Pricing'!$V$7:$V$56,MATCH(LARGE('Menu Pricing'!$Z$7:$Z$56,1),'Menu Pricing'!$Z$7:$Z$56,0)),""),"") | H35: =IFERROR(IF(AND(LARGE('Menu Pricing'!$Z$7:$Z$56,1)>=1,INDEX('Menu Pricing'!$V$7:$V$56,MATCH(LARGE('Menu Pricing'!$Z$7:$Z$56,1),'Menu Pricing'!$Z$7:$Z$56,0))>0),IF(N(INDEX('Menu Pricing'!$W$7:$W$56,MATCH(LARGE('Menu Pricing'!$Z$7:$Z$56,1),'Menu Pricing'!$Z$7:$Z$56,0)))<0,"-","")&cfg_Symbol&TEXT(ABS(N(INDEX('Menu Pricing'!$W$7:$W$56,MATCH(LARGE('Menu Pricing'!$Z$7:$Z$56,1),'Menu Pricing'!$Z$7:$Z$56,0)))),"#,##0"),""),"") | J35: =IFERROR(IF(AND(LARGE('Menu Pricing'!$AA$7:$AA$56,1)>-1E+14,INDEX('Menu Pricing'!$V$7:$V$56,MATCH(LARGE('Menu Pricing'!$AA$7:$AA$56,1),'Menu Pricing'!$AA$7:$AA$56,0))>0),"1. "&INDEX('Menu Pricing'!$B$7:$B$56,MATCH(LARGE('Menu Pricing'!$AA$7:$AA$56,1),'Menu Pricing'!$AA$7:$AA$56,0)),IF(1=1,"No sales in this period yet","")),"") | N35: =IFERROR(IF(AND(LARGE('Menu Pricing'!$AA$7:$AA$56,1)>-1E+14,INDEX('Menu Pricing'!$V$7:$V$56,MATCH(LARGE('Menu Pricing'!$AA$7:$AA$56,1),'Menu Pricing'!$AA$7:$AA$56,0))>0),INDEX('Menu Pricing'!$X$7:$X$56,MATCH(LARGE('Menu Pricing'!$AA$7:$AA$56,1),'Menu Pricing'!$AA$7:$AA$56,0)),""),"") | P35: =IFERROR(IF(AND(LARGE('Menu Pricing'!$AA$7:$AA$56,1)>-1E+14,INDEX('Menu Pricing'!$V$7:$V$56,MATCH(LARGE('Menu Pricing'!$AA$7:$AA$56,1),'Menu Pricing'!$AA$7:$AA$56,0))>0),INDEX('Menu Pricing'!$T$7:$T$56,MATCH(LARGE('Menu Pricing'!$AA$7:$AA$56,1),'Menu Pricing'!$AA$7:$AA$56,0)),""),"")
B36: =IFERROR(IF(AND(LARGE('Menu Pricing'!$Z$7:$Z$56,2)>=1,INDEX('Menu Pricing'!$V$7:$V$56,MATCH(LARGE('Menu Pricing'!$Z$7:$Z$56,2),'Menu Pricing'!$Z$7:$Z$56,0))>0),"2. "&INDEX('Menu Pricing'!$B$7:$B$56,MATCH(LARGE('Menu Pricing'!$Z$7:$Z$56,2),'Menu Pricing'!$Z$7:$Z$56,0)),IF(2=1,"No sales in this period yet","")),"") | F36: =IFERROR(IF(AND(LARGE('Menu Pricing'!$Z$7:$Z$56,2)>=1,INDEX('Menu Pricing'!$V$7:$V$56,MATCH(LARGE('Menu Pricing'!$Z$7:$Z$56,2),'Menu Pricing'!$Z$7:$Z$56,0))>0),INDEX('Menu Pricing'!$V$7:$V$56,MATCH(LARGE('Menu Pricing'!$Z$7:$Z$56,2),'Menu Pricing'!$Z$7:$Z$56,0)),""),"") | H36: =IFERROR(IF(AND(LARGE('Menu Pricing'!$Z$7:$Z$56,2)>=1,INDEX('Menu Pricing'!$V$7:$V$56,MATCH(LARGE('Menu Pricing'!$Z$7:$Z$56,2),'Menu Pricing'!$Z$7:$Z$56,0))>0),IF(N(INDEX('Menu Pricing'!$W$7:$W$56,MATCH(LARGE('Menu Pricing'!$Z$7:$Z$56,2),'Menu Pricing'!$Z$7:$Z$56,0)))<0,"-","")&cfg_Symbol&TEXT(ABS(N(INDEX('Menu Pricing'!$W$7:$W$56,MATCH(LARGE('Menu Pricing'!$Z$7:$Z$56,2),'Menu Pricing'!$Z$7:$Z$56,0)))),"#,##0"),""),"") | J36: =IFERROR(IF(AND(LARGE('Menu Pricing'!$AA$7:$AA$56,2)>-1E+14,INDEX('Menu Pricing'!$V$7:$V$56,MATCH(LARGE('Menu Pricing'!$AA$7:$AA$56,2),'Menu Pricing'!$AA$7:$AA$56,0))>0),"2. "&INDEX('Menu Pricing'!$B$7:$B$56,MATCH(LARGE('Menu Pricing'!$AA$7:$AA$56,2),'Menu Pricing'!$AA$7:$AA$56,0)),IF(2=1,"No sales in this period yet","")),"") | N36: =IFERROR(IF(AND(LARGE('Menu Pricing'!$AA$7:$AA$56,2)>-1E+14,INDEX('Menu Pricing'!$V$7:$V$56,MATCH(LARGE('Menu Pricing'!$AA$7:$AA$56,2),'Menu Pricing'!$AA$7:$AA$56,0))>0),INDEX('Menu Pricing'!$X$7:$X$56,MATCH(LARGE('Menu Pricing'!$AA$7:$AA$56,2),'Menu Pricing'!$AA$7:$AA$56,0)),""),"") | P36: =IFERROR(IF(AND(LARGE('Menu Pricing'!$AA$7:$AA$56,2)>-1E+14,INDEX('Menu Pricing'!$V$7:$V$56,MATCH(LARGE('Menu Pricing'!$AA$7:$AA$56,2),'Menu Pricing'!$AA$7:$AA$56,0))>0),INDEX('Menu Pricing'!$T$7:$T$56,MATCH(LARGE('Menu Pricing'!$AA$7:$AA$56,2),'Menu Pricing'!$AA$7:$AA$56,0)),""),"")
B37: =IFERROR(IF(AND(LARGE('Menu Pricing'!$Z$7:$Z$56,3)>=1,INDEX('Menu Pricing'!$V$7:$V$56,MATCH(LARGE('Menu Pricing'!$Z$7:$Z$56,3),'Menu Pricing'!$Z$7:$Z$56,0))>0),"3. "&INDEX('Menu Pricing'!$B$7:$B$56,MATCH(LARGE('Menu Pricing'!$Z$7:$Z$56,3),'Menu Pricing'!$Z$7:$Z$56,0)),IF(3=1,"No sales in this period yet","")),"") | F37: =IFERROR(IF(AND(LARGE('Menu Pricing'!$Z$7:$Z$56,3)>=1,INDEX('Menu Pricing'!$V$7:$V$56,MATCH(LARGE('Menu Pricing'!$Z$7:$Z$56,3),'Menu Pricing'!$Z$7:$Z$56,0))>0),INDEX('Menu Pricing'!$V$7:$V$56,MATCH(LARGE('Menu Pricing'!$Z$7:$Z$56,3),'Menu Pricing'!$Z$7:$Z$56,0)),""),"") | H37: =IFERROR(IF(AND(LARGE('Menu Pricing'!$Z$7:$Z$56,3)>=1,INDEX('Menu Pricing'!$V$7:$V$56,MATCH(LARGE('Menu Pricing'!$Z$7:$Z$56,3),'Menu Pricing'!$Z$7:$Z$56,0))>0),IF(N(INDEX('Menu Pricing'!$W$7:$W$56,MATCH(LARGE('Menu Pricing'!$Z$7:$Z$56,3),'Menu Pricing'!$Z$7:$Z$56,0)))<0,"-","")&cfg_Symbol&TEXT(ABS(N(INDEX('Menu Pricing'!$W$7:$W$56,MATCH(LARGE('Menu Pricing'!$Z$7:$Z$56,3),'Menu Pricing'!$Z$7:$Z$56,0)))),"#,##0"),""),"") | J37: =IFERROR(IF(AND(LARGE('Menu Pricing'!$AA$7:$AA$56,3)>-1E+14,INDEX('Menu Pricing'!$V$7:$V$56,MATCH(LARGE('Menu Pricing'!$AA$7:$AA$56,3),'Menu Pricing'!$AA$7:$AA$56,0))>0),"3. "&INDEX('Menu Pricing'!$B$7:$B$56,MATCH(LARGE('Menu Pricing'!$AA$7:$AA$56,3),'Menu Pricing'!$AA$7:$AA$56,0)),IF(3=1,"No sales in this period yet","")),"") | N37: =IFERROR(IF(AND(LARGE('Menu Pricing'!$AA$7:$AA$56,3)>-1E+14,INDEX('Menu Pricing'!$V$7:$V$56,MATCH(LARGE('Menu Pricing'!$AA$7:$AA$56,3),'Menu Pricing'!$AA$7:$AA$56,0))>0),INDEX('Menu Pricing'!$X$7:$X$56,MATCH(LARGE('Menu Pricing'!$AA$7:$AA$56,3),'Menu Pricing'!$AA$7:$AA$56,0)),""),"") | P37: =IFERROR(IF(AND(LARGE('Menu Pricing'!$AA$7:$AA$56,3)>-1E+14,INDEX('Menu Pricing'!$V$7:$V$56,MATCH(LARGE('Menu Pricing'!$AA$7:$AA$56,3),'Menu Pricing'!$AA$7:$AA$56,0))>0),INDEX('Menu Pricing'!$T$7:$T$56,MATCH(LARGE('Menu Pricing'!$AA$7:$AA$56,3),'Menu Pricing'!$AA$7:$AA$56,0)),""),"")
B38: =IFERROR(IF(AND(LARGE('Menu Pricing'!$Z$7:$Z$56,4)>=1,INDEX('Menu Pricing'!$V$7:$V$56,MATCH(LARGE('Menu Pricing'!$Z$7:$Z$56,4),'Menu Pricing'!$Z$7:$Z$56,0))>0),"4. "&INDEX('Menu Pricing'!$B$7:$B$56,MATCH(LARGE('Menu Pricing'!$Z$7:$Z$56,4),'Menu Pricing'!$Z$7:$Z$56,0)),IF(4=1,"No sales in this period yet","")),"") | F38: =IFERROR(IF(AND(LARGE('Menu Pricing'!$Z$7:$Z$56,4)>=1,INDEX('Menu Pricing'!$V$7:$V$56,MATCH(LARGE('Menu Pricing'!$Z$7:$Z$56,4),'Menu Pricing'!$Z$7:$Z$56,0))>0),INDEX('Menu Pricing'!$V$7:$V$56,MATCH(LARGE('Menu Pricing'!$Z$7:$Z$56,4),'Menu Pricing'!$Z$7:$Z$56,0)),""),"") | H38: =IFERROR(IF(AND(LARGE('Menu Pricing'!$Z$7:$Z$56,4)>=1,INDEX('Menu Pricing'!$V$7:$V$56,MATCH(LARGE('Menu Pricing'!$Z$7:$Z$56,4),'Menu Pricing'!$Z$7:$Z$56,0))>0),IF(N(INDEX('Menu Pricing'!$W$7:$W$56,MATCH(LARGE('Menu Pricing'!$Z$7:$Z$56,4),'Menu Pricing'!$Z$7:$Z$56,0)))<0,"-","")&cfg_Symbol&TEXT(ABS(N(INDEX('Menu Pricing'!$W$7:$W$56,MATCH(LARGE('Menu Pricing'!$Z$7:$Z$56,4),'Menu Pricing'!$Z$7:$Z$56,0)))),"#,##0"),""),"") | J38: =IFERROR(IF(AND(LARGE('Menu Pricing'!$AA$7:$AA$56,4)>-1E+14,INDEX('Menu Pricing'!$V$7:$V$56,MATCH(LARGE('Menu Pricing'!$AA$7:$AA$56,4),'Menu Pricing'!$AA$7:$AA$56,0))>0),"4. "&INDEX('Menu Pricing'!$B$7:$B$56,MATCH(LARGE('Menu Pricing'!$AA$7:$AA$56,4),'Menu Pricing'!$AA$7:$AA$56,0)),IF(4=1,"No sales in this period yet","")),"") | N38: =IFERROR(IF(AND(LARGE('Menu Pricing'!$AA$7:$AA$56,4)>-1E+14,INDEX('Menu Pricing'!$V$7:$V$56,MATCH(LARGE('Menu Pricing'!$AA$7:$AA$56,4),'Menu Pricing'!$AA$7:$AA$56,0))>0),INDEX('Menu Pricing'!$X$7:$X$56,MATCH(LARGE('Menu Pricing'!$AA$7:$AA$56,4),'Menu Pricing'!$AA$7:$AA$56,0)),""),"") | P38: =IFERROR(IF(AND(LARGE('Menu Pricing'!$AA$7:$AA$56,4)>-1E+14,INDEX('Menu Pricing'!$V$7:$V$56,MATCH(LARGE('Menu Pricing'!$AA$7:$AA$56,4),'Menu Pricing'!$AA$7:$AA$56,0))>0),INDEX('Menu Pricing'!$T$7:$T$56,MATCH(LARGE('Menu Pricing'!$AA$7:$AA$56,4),'Menu Pricing'!$AA$7:$AA$56,0)),""),"")
B39: =IFERROR(IF(AND(LARGE('Menu Pricing'!$Z$7:$Z$56,5)>=1,INDEX('Menu Pricing'!$V$7:$V$56,MATCH(LARGE('Menu Pricing'!$Z$7:$Z$56,5),'Menu Pricing'!$Z$7:$Z$56,0))>0),"5. "&INDEX('Menu Pricing'!$B$7:$B$56,MATCH(LARGE('Menu Pricing'!$Z$7:$Z$56,5),'Menu Pricing'!$Z$7:$Z$56,0)),IF(5=1,"No sales in this period yet","")),"") | F39: =IFERROR(IF(AND(LARGE('Menu Pricing'!$Z$7:$Z$56,5)>=1,INDEX('Menu Pricing'!$V$7:$V$56,MATCH(LARGE('Menu Pricing'!$Z$7:$Z$56,5),'Menu Pricing'!$Z$7:$Z$56,0))>0),INDEX('Menu Pricing'!$V$7:$V$56,MATCH(LARGE('Menu Pricing'!$Z$7:$Z$56,5),'Menu Pricing'!$Z$7:$Z$56,0)),""),"") | H39: =IFERROR(IF(AND(LARGE('Menu Pricing'!$Z$7:$Z$56,5)>=1,INDEX('Menu Pricing'!$V$7:$V$56,MATCH(LARGE('Menu Pricing'!$Z$7:$Z$56,5),'Menu Pricing'!$Z$7:$Z$56,0))>0),IF(N(INDEX('Menu Pricing'!$W$7:$W$56,MATCH(LARGE('Menu Pricing'!$Z$7:$Z$56,5),'Menu Pricing'!$Z$7:$Z$56,0)))<0,"-","")&cfg_Symbol&TEXT(ABS(N(INDEX('Menu Pricing'!$W$7:$W$56,MATCH(LARGE('Menu Pricing'!$Z$7:$Z$56,5),'Menu Pricing'!$Z$7:$Z$56,0)))),"#,##0"),""),"") | J39: =IFERROR(IF(AND(LARGE('Menu Pricing'!$AA$7:$AA$56,5)>-1E+14,INDEX('Menu Pricing'!$V$7:$V$56,MATCH(LARGE('Menu Pricing'!$AA$7:$AA$56,5),'Menu Pricing'!$AA$7:$AA$56,0))>0),"5. "&INDEX('Menu Pricing'!$B$7:$B$56,MATCH(LARGE('Menu Pricing'!$AA$7:$AA$56,5),'Menu Pricing'!$AA$7:$AA$56,0)),IF(5=1,"No sales in this period yet","")),"") | N39: =IFERROR(IF(AND(LARGE('Menu Pricing'!$AA$7:$AA$56,5)>-1E+14,INDEX('Menu Pricing'!$V$7:$V$56,MATCH(LARGE('Menu Pricing'!$AA$7:$AA$56,5),'Menu Pricing'!$AA$7:$AA$56,0))>0),INDEX('Menu Pricing'!$X$7:$X$56,MATCH(LARGE('Menu Pricing'!$AA$7:$AA$56,5),'Menu Pricing'!$AA$7:$AA$56,0)),""),"") | P39: =IFERROR(IF(AND(LARGE('Menu Pricing'!$AA$7:$AA$56,5)>-1E+14,INDEX('Menu Pricing'!$V$7:$V$56,MATCH(LARGE('Menu Pricing'!$AA$7:$AA$56,5),'Menu Pricing'!$AA$7:$AA$56,0))>0),INDEX('Menu Pricing'!$T$7:$T$56,MATCH(LARGE('Menu Pricing'!$AA$7:$AA$56,5),'Menu Pricing'!$AA$7:$AA$56,0)),""),"")
B41: ALERTS & DATA CHECKS
B42: =COUNTIF('Menu Pricing'!$T$7:$T$56,"LOSS") | C42: menu item(s) priced BELOW cost | H42: Open › | J42: =SUMPRODUCT(('Recipe Builder'!$G$7:$G$406<>"")*('Recipe Builder'!$G$7:$G$406<>"OK")) | K42: recipe line(s) with a unit or setup problem | P42: Open ›
B43: =COUNTIF('Menu Pricing'!$T$7:$T$56,"Below target") | C43: menu item(s) below your target margin | H43: Open › | J43: =SUMPRODUCT(('Sales Log'!$N$7:$N$3006<>"")*('Sales Log'!$N$7:$N$3006<>"OK")) | K43: sales row(s) that need fixing (not counted) | P43: Open ›
B44: =COUNTIF('Inventory'!$P$7:$P$106,"Reorder") | C44: ingredient(s) at or below reorder level | H44: Open › | J44: =ps_unclassified | K44: expense row(s) that need fixing (not counted) | P44: Open ›
B45: =COUNTIF('Inventory'!$P$7:$P$106,"Recount (negative)") | C45: ingredient(s) with negative stock - recount | H45: Open › | J45: =SUMPRODUCT(('Waste Log'!$H$7:$H$506<>"")*('Waste Log'!$H$7:$H$506<>"OK")) | K45: waste row(s) that need fixing (not counted) | P45: Open ›
B47: ="Profit model: Revenue - COGS (recipe cost x items sold) = Gross profit; minus waste and operating expenses = Net profit. Ingredient purchases and owner's draw are excluded so nothing is counted twice. · NoviraNest v1.0.0"

Sheet Settings
B2: Settings | F2: NoviraNest
B3: Set these once. Every sheet reads from here.
B4: › Start Here | C4: › Dashboard | D4: › Menu Pricing
B5: Setting | C5: Your value | E5: What it does
B6: Business name | C6: Your Food Truck Name | E6: Shown on the Dashboard title.
B7: Currency | C7: USD | E7: USD ($) or GBP (£). Changes symbols and formats only - amounts are NOT converted.
B8: Reporting year | C8: 2026 | E8: The year shown in the Monthly Report and Dashboard charts.
B9: Dashboard period | C9: Full Year | E9: Full Year or a single month of the reporting year. KPI cards and item rankings follow this.
B10: Labour cost per hour (incl. payroll taxes) | E10: Used only to price prep time on Menu Pricing. Real wages go in Expenses (no double counting).
B11: Default target profit margin | C11: 0.6 | E11: Margin = profit / price. Used for suggested prices unless an item has its own target.
B12: Target food cost % | C12: 0.32 | E12: Ingredient cost / price. Items above this are flagged 'High food cost'. Typical: 25-35%.
B13: Round suggested prices up to | C13: 0.25 | E13: Suggested prices are rounded UP to this step (0 = no rounding).
B14: Last stock count date | E14: Date you last counted stock. Inventory usage and waste are counted from this date.
B17: AUTOMATIC VALUES (used by formulas - do not edit)
B18: Currency symbol | C18: =IF($C$7="GBP","£","$")
B19: Active currency | C19: =IF($C$7="GBP","GBP","USD")
B20: Period month (0 = full year) | C20: =IFERROR(MATCH($C$9,lst_Period,0)-1,0)
B21: Reporting year used | C21: =IF(AND(ISNUMBER($C$8),$C$8>=2000,$C$8<=2100),INT($C$8),2026)
B22: Period start | C22: =IF($C$20=0,DATE($C$21,1,1),DATE($C$21,$C$20,1))
B23: Period end | C23: =IF($C$20=0,DATE($C$21,12,31),EOMONTH($C$22,0))
B24: Months in period | C24: =IF($C$20=0,12,1)
B25: Period label | C25: =IF($C$20=0,"Full Year "&$C$21,$C$9&" "&$C$21)
B26: Stock count date used | C26: =IF(ISNUMBER($C$14),$C$14,DATE(2000,1,1))
B27: Labour rate used | C27: =N($C$10)
B28: Target margin used | C28: =IF(AND(ISNUMBER($C$11),$C$11<0.95),MAX(0,$C$11),0.6)
B29: Food cost target used | C29: =IF(ISNUMBER($C$12),$C$12,0.32)
B30: Rounding step used | C30: =IF(AND(ISNUMBER($C$13),$C$13>0),$C$13,0)
B32: Tip: switch Dashboard period to a month (e.g. 'July') to see that month's KPIs and best sellers. Charts on the Dashboard always show all 12 months of the reporting year.

Sheet Menu Pricing
B2: Smart Menu Pricing | Y2: NoviraNest
B3: Cost per serving, suggested price, real margin vs markup, and what to fix. Sales columns follow the Dashboard period.
B4: › Start Here | C4: › Dashboard | E4: › Recipe Builder | G4: › Settings
B5: ITEM | D5: COST PER SERVING | L5: PRICING TARGET | O5: YOUR PRICE & RESULT | V5: SALES (DASHBOARD PERIOD)
B6: Menu item | C6: Category | D6: ="Recipe ingredients ("&cfg_Symbol&")" | E6: ="Ingredient override ("&cfg_Symbol&")" | F6: ="Ingredient cost used ("&cfg_Symbol&")" | G6: ="Packaging ("&cfg_Symbol&")" | H6: Prep minutes | I6: ="Prep labour ("&cfg_Symbol&")" | J6: ="Other variable ("&cfg_Symbol&")" | K6: ="TOTAL COST per serving ("&cfg_Symbol&")" | L6: Target margin | M6: Target used | N6: ="Suggested price ("&cfg_Symbol&")" | O6: ="YOUR MENU PRICE ("&cfg_Symbol&")" | P6: ="Profit per serving ("&cfg_Symbol&")" | Q6: Actual margin | R6: Markup on cost | S6: Food cost % | T6: Status | U6: Recommendation | V6: Items sold | W6: ="Revenue ("&cfg_Symbol&")" | X6: ="Gross profit ("&cfg_Symbol&")" | Y6: Sales mix
D7: =IF($B7="","",SUMIFS('Recipe Builder'!$J$7:$J$406,'Recipe Builder'!$B$7:$B$406,$B7)) | F7: =IF($B7="","",IF(ISNUMBER($E7),$E7,N($D7))) | I7: =IF($B7="","",N($H7)/60*cfg_LaborRate) | K7: =IF($B7="","",$F7+N($G7)+$I7+N($J7)) | M7: =IF($B7="","",IF(AND(ISNUMBER($L7),$L7<0.95),MAX(0,$L7),cfg_TargetMargin)) | N7: =IF($B7="","",IF(cfg_Round>0,CEILING($K7/(1-$M7),cfg_Round),ROUND($K7/(1-$M7),2))) | P7: =IF(OR($B7="",N($O7)<=0),"",$O7-$K7) | Q7: =IF(OR($B7="",N($O7)<=0),"",$P7/$O7) | R7: =IF(OR($B7="",N($O7)<=0,N($K7)<=0),"",$P7/$K7) | S7: =IF(OR($B7="",N($O7)<=0),"",$F7/$O7) | T7: =IF($B7="","",IF(COUNTIF($B$7:$B$56,$B7)>1,"Duplicate name",IF(N($O7)<=0,"Set a price",IF(N($K7)<=0,"Add costs",IF($P7<0,"LOSS",IF($Q7<$M7-0.00001,"Below target",IF($S7>cfg_FoodCostTarget,"High food cost","Healthy"))))))) | U7: =IF($T7="","",IF($T7="Duplicate name","Each menu item needs a unique name",IF($T7="Set a price","Suggested starting price: "&cfg_Symbol&TEXT($N7,"0.00"),IF($T7="Add costs","Build the recipe or type an ingredient cost override",IF($T7="LOSS","Losing "&cfg_Symbol&TEXT(-$P7,"0.00")&" per sale - raise to "&cfg_Symbol&TEXT($N7,"0.00"),IF($T7="Below target","Raise to "&cfg_Symbol&TEXT($N7,"0.00")&" for a "&TEXT($M7,"0%")&" margin",IF($T7="High food cost","Margin OK; food cost "&TEXT($S7,"0%")&" is above "&TEXT(cfg_FoodCostTarget,"0%")&" target","On target"))))))) | V7: =IF($B7="","",SUMIFS('Sales Log'!$D$7:$D$3006,'Sales Log'!$C$7:$C$3006,$B7,'Sales Log'!$B$7:$B$3006,">="&cfg_Start,'Sales Log'!$B$7:$B$3006,"<="&cfg_End,'Sales Log'!$N$7:$N$3006,"OK")) | W7: =IF($B7="","",SUMIFS('Sales Log'!$I$7:$I$3006,'Sales Log'!$C$7:$C$3006,$B7,'Sales Log'!$B$7:$B$3006,">="&cfg_Start,'Sales Log'!$B$7:$B$3006,"<="&cfg_End,'Sales Log'!$N$7:$N$3006,"OK")) | X7: =IF($B7="","",SUMIFS('Sales Log'!$L$7:$L$3006,'Sales Log'!$C$7:$C$3006,$B7,'Sales Log'!$B$7:$B$3006,">="&cfg_Start,'Sales Log'!$B$7:$B$3006,"<="&cfg_End,'Sales Log'!$N$7:$N$3006,"OK")) | Y7: =IF($B7="","",IF(SUM($V$7:$V$56)=0,0,$V7/SUM($V$7:$V$56))) | Z7: =IF($B7="",-1,N($V7)+ROW()/1000000) | AA7: =IF($B7="",-1E+15,N($X7)+ROW()/1000000)
D8: =IF($B8="","",SUMIFS('Recipe Builder'!$J$7:$J$406,'Recipe Builder'!$B$7:$B$406,$B8)) | F8: =IF($B8="","",IF(ISNUMBER($E8),$E8,N($D8))) | I8: =IF($B8="","",N($H8)/60*cfg_LaborRate) | K8: =IF($B8="","",$F8+N($G8)+$I8+N($J8)) | M8: =IF($B8="","",IF(AND(ISNUMBER($L8),$L8<0.95),MAX(0,$L8),cfg_TargetMargin)) | N8: =IF($B8="","",IF(cfg_Round>0,CEILING($K8/(1-$M8),cfg_Round),ROUND($K8/(1-$M8),2))) | P8: =IF(OR($B8="",N($O8)<=0),"",$O8-$K8) | Q8: =IF(OR($B8="",N($O8)<=0),"",$P8/$O8) | R8: =IF(OR($B8="",N($O8)<=0,N($K8)<=0),"",$P8/$K8) | S8: =IF(OR($B8="",N($O8)<=0),"",$F8/$O8) | T8: =IF($B8="","",IF(COUNTIF($B$7:$B$56,$B8)>1,"Duplicate name",IF(N($O8)<=0,"Set a price",IF(N($K8)<=0,"Add costs",IF($P8<0,"LOSS",IF($Q8<$M8-0.00001,"Below target",IF($S8>cfg_FoodCostTarget,"High food cost","Healthy"))))))) | U8: =IF($T8="","",IF($T8="Duplicate name","Each menu item needs a unique name",IF($T8="Set a price","Suggested starting price: "&cfg_Symbol&TEXT($N8,"0.00"),IF($T8="Add costs","Build the recipe or type an ingredient cost override",IF($T8="LOSS","Losing "&cfg_Symbol&TEXT(-$P8,"0.00")&" per sale - raise to "&cfg_Symbol&TEXT($N8,"0.00"),IF($T8="Below target","Raise to "&cfg_Symbol&TEXT($N8,"0.00")&" for a "&TEXT($M8,"0%")&" margin",IF($T8="High food cost","Margin OK; food cost "&TEXT($S8,"0%")&" is above "&TEXT(cfg_FoodCostTarget,"0%")&" target","On target"))))))) | V8: =IF($B8="","",SUMIFS('Sales Log'!$D$7:$D$3006,'Sales Log'!$C$7:$C$3006,$B8,'Sales Log'!$B$7:$B$3006,">="&cfg_Start,'Sales Log'!$B$7:$B$3006,"<="&cfg_End,'Sales Log'!$N$7:$N$3006,"OK")) | W8: =IF($B8="","",SUMIFS('Sales Log'!$I$7:$I$3006,'Sales Log'!$C$7:$C$3006,$B8,'Sales Log'!$B$7:$B$3006,">="&cfg_Start,'Sales Log'!$B$7:$B$3006,"<="&cfg_End,'Sales Log'!$N$7:$N$3006,"OK")) | X8: =IF($B8="","",SUMIFS('Sales Log'!$L$7:$L$3006,'Sales Log'!$C$7:$C$3006,$B8,'Sales Log'!$B$7:$B$3006,">="&cfg_Start,'Sales Log'!$B$7:$B$3006,"<="&cfg_End,'Sales Log'!$N$7:$N$3006,"OK")) | Y8: =IF($B8="","",IF(SUM($V$7:$V$56)=0,0,$V8/SUM($V$7:$V$56))) | Z8: =IF($B8="",-1,N($V8)+ROW()/1000000) | AA8: =IF($B8="",-1E+15,N($X8)+ROW()/1000000)
D9: =IF($B9="","",SUMIFS('Recipe Builder'!$J$7:$J$406,'Recipe Builder'!$B$7:$B$406,$B9)) | F9: =IF($B9="","",IF(ISNUMBER($E9),$E9,N($D9))) | I9: =IF($B9="","",N($H9)/60*cfg_LaborRate) | K9: =IF($B9="","",$F9+N($G9)+$I9+N($J9)) | M9: =IF($B9="","",IF(AND(ISNUMBER($L9),$L9<0.95),MAX(0,$L9),cfg_TargetMargin)) | N9: =IF($B9="","",IF(cfg_Round>0,CEILING($K9/(1-$M9),cfg_Round),ROUND($K9/(1-$M9),2))) | P9: =IF(OR($B9="",N($O9)<=0),"",$O9-$K9) | Q9: =IF(OR($B9="",N($O9)<=0),"",$P9/$O9) | R9: =IF(OR($B9="",N($O9)<=0,N($K9)<=0),"",$P9/$K9) | S9: =IF(OR($B9="",N($O9)<=0),"",$F9/$O9) | T9: =IF($B9="","",IF(COUNTIF($B$7:$B$56,$B9)>1,"Duplicate name",IF(N($O9)<=0,"Set a price",IF(N($K9)<=0,"Add costs",IF($P9<0,"LOSS",IF($Q9<$M9-0.00001,"Below target",IF($S9>cfg_FoodCostTarget,"High food cost","Healthy"))))))) | U9: =IF($T9="","",IF($T9="Duplicate name","Each menu item needs a unique name",IF($T9="Set a price","Suggested starting price: "&cfg_Symbol&TEXT($N9,"0.00"),IF($T9="Add costs","Build the recipe or type an ingredient cost override",IF($T9="LOSS","Losing "&cfg_Symbol&TEXT(-$P9,"0.00")&" per sale - raise to "&cfg_Symbol&TEXT($N9,"0.00"),IF($T9="Below target","Raise to "&cfg_Symbol&TEXT($N9,"0.00")&" for a "&TEXT($M9,"0%")&" margin",IF($T9="High food cost","Margin OK; food cost "&TEXT($S9,"0%")&" is above "&TEXT(cfg_FoodCostTarget,"0%")&" target","On target"))))))) | V9: =IF($B9="","",SUMIFS('Sales Log'!$D$7:$D$3006,'Sales Log'!$C$7:$C$3006,$B9,'Sales Log'!$B$7:$B$3006,">="&cfg_Start,'Sales Log'!$B$7:$B$3006,"<="&cfg_End,'Sales Log'!$N$7:$N$3006,"OK")) | W9: =IF($B9="","",SUMIFS('Sales Log'!$I$7:$I$3006,'Sales Log'!$C$7:$C$3006,$B9,'Sales Log'!$B$7:$B$3006,">="&cfg_Start,'Sales Log'!$B$7:$B$3006,"<="&cfg_End,'Sales Log'!$N$7:$N$3006,"OK")) | X9: =IF($B9="","",SUMIFS('Sales Log'!$L$7:$L$3006,'Sales Log'!$C$7:$C$3006,$B9,'Sales Log'!$B$7:$B$3006,">="&cfg_Start,'Sales Log'!$B$7:$B$3006,"<="&cfg_End,'Sales Log'!$N$7:$N$3006,"OK")) | Y9: =IF($B9="","",IF(SUM($V$7:$V$56)=0,0,$V9/SUM($V$7:$V$56))) | Z9: =IF($B9="",-1,N($V9)+ROW()/1000000) | AA9: =IF($B9="",-1E+15,N($X9)+ROW()/1000000)
D10: =IF($B10="","",SUMIFS('Recipe Builder'!$J$7:$J$406,'Recipe Builder'!$B$7:$B$406,$B10)) | F10: =IF($B10="","",IF(ISNUMBER($E10),$E10,N($D10))) | I10: =IF($B10="","",N($H10)/60*cfg_LaborRate) | K10: =IF($B10="","",$F10+N($G10)+$I10+N($J10)) | M10: =IF($B10="","",IF(AND(ISNUMBER($L10),$L10<0.95),MAX(0,$L10),cfg_TargetMargin)) | N10: =IF($B10="","",IF(cfg_Round>0,CEILING($K10/(1-$M10),cfg_Round),ROUND($K10/(1-$M10),2))) | P10: =IF(OR($B10="",N($O10)<=0),"",$O10-$K10) | Q10: =IF(OR($B10="",N($O10)<=0),"",$P10/$O10) | R10: =IF(OR($B10="",N($O10)<=0,N($K10)<=0),"",$P10/$K10) | S10: =IF(OR($B10="",N($O10)<=0),"",$F10/$O10) | T10: =IF($B10="","",IF(COUNTIF($B$7:$B$56,$B10)>1,"Duplicate name",IF(N($O10)<=0,"Set a price",IF(N($K10)<=0,"Add costs",IF($P10<0,"LOSS",IF($Q10<$M10-0.00001,"Below target",IF($S10>cfg_FoodCostTarget,"High food cost","Healthy"))))))) | U10: =IF($T10="","",IF($T10="Duplicate name","Each menu item needs a unique name",IF($T10="Set a price","Suggested starting price: "&cfg_Symbol&TEXT($N10,"0.00"),IF($T10="Add costs","Build the recipe or type an ingredient cost override",IF($T10="LOSS","Losing "&cfg_Symbol&TEXT(-$P10,"0.00")&" per sale - raise to "&cfg_Symbol&TEXT($N10,"0.00"),IF($T10="Below target","Raise to "&cfg_Symbol&TEXT($N10,"0.00")&" for a "&TEXT($M10,"0%")&" margin",IF($T10="High food cost","Margin OK; food cost "&TEXT($S10,"0%")&" is above "&TEXT(cfg_FoodCostTarget,"0%")&" target","On target"))))))) | V10: =IF($B10="","",SUMIFS('Sales Log'!$D$7:$D$3006,'Sales Log'!$C$7:$C$3006,$B10,'Sales Log'!$B$7:$B$3006,">="&cfg_Start,'Sales Log'!$B$7:$B$3006,"<="&cfg_End,'Sales Log'!$N$7:$N$3006,"OK")) | W10: =IF($B10="","",SUMIFS('Sales Log'!$I$7:$I$3006,'Sales Log'!$C$7:$C$3006,$B10,'Sales Log'!$B$7:$B$3006,">="&cfg_Start,'Sales Log'!$B$7:$B$3006,"<="&cfg_End,'Sales Log'!$N$7:$N$3006,"OK")) | X10: =IF($B10="","",SUMIFS('Sales Log'!$L$7:$L$3006,'Sales Log'!$C$7:$C$3006,$B10,'Sales Log'!$B$7:$B$3006,">="&cfg_Start,'Sales Log'!$B$7:$B$3006,"<="&cfg_End,'Sales Log'!$N$7:$N$3006,"OK")) | Y10: =IF($B10="","",IF(SUM($V$7:$V$56)=0,0,$V10/SUM($V$7:$V$56))) | Z10: =IF($B10="",-1,N($V10)+ROW()/1000000) | AA10: =IF($B10="",-1E+15,N($X10)+ROW()/1000000)
D11: =IF($B11="","",SUMIFS('Recipe Builder'!$J$7:$J$406,'Recipe Builder'!$B$7:$B$406,$B11)) | F11: =IF($B11="","",IF(ISNUMBER($E11),$E11,N($D11))) | I11: =IF($B11="","",N($H11)/60*cfg_LaborRate) | K11: =IF($B11="","",$F11+N($G11)+$I11+N($J11)) | M11: =IF($B11="","",IF(AND(ISNUMBER($L11),$L11<0.95),MAX(0,$L11),cfg_TargetMargin)) | N11: =IF($B11="","",IF(cfg_Round>0,CEILING($K11/(1-$M11),cfg_Round),ROUND($K11/(1-$M11),2))) | P11: =IF(OR($B11="",N($O11)<=0),"",$O11-$K11) | Q11: =IF(OR($B11="",N($O11)<=0),"",$P11/$O11) | R11: =IF(OR($B11="",N($O11)<=0,N($K11)<=0),"",$P11/$K11) | S11: =IF(OR($B11="",N($O11)<=0),"",$F11/$O11) | T11: =IF($B11="","",IF(COUNTIF($B$7:$B$56,$B11)>1,"Duplicate name",IF(N($O11)<=0,"Set a price",IF(N($K11)<=0,"Add costs",IF($P11<0,"LOSS",IF($Q11<$M11-0.00001,"Below target",IF($S11>cfg_FoodCostTarget,"High food cost","Healthy"))))))) | U11: =IF($T11="","",IF($T11="Duplicate name","Each menu item needs a unique name",IF($T11="Set a price","Suggested starting price: "&cfg_Symbol&TEXT($N11,"0.00"),IF($T11="Add costs","Build the recipe or type an ingredient cost override",IF($T11="LOSS","Losing "&cfg_Symbol&TEXT(-$P11,"0.00")&" per sale - raise to "&cfg_Symbol&TEXT($N11,"0.00"),IF($T11="Below target","Raise to "&cfg_Symbol&TEXT($N11,"0.00")&" for a "&TEXT($M11,"0%")&" margin",IF($T11="High food cost","Margin OK; food cost "&TEXT($S11,"0%")&" is above "&TEXT(cfg_FoodCostTarget,"0%")&" target","On target"))))))) | V11: =IF($B11="","",SUMIFS('Sales Log'!$D$7:$D$3006,'Sales Log'!$C$7:$C$3006,$B11,'Sales Log'!$B$7:$B$3006,">="&cfg_Start,'Sales Log'!$B$7:$B$3006,"<="&cfg_End,'Sales Log'!$N$7:$N$3006,"OK")) | W11: =IF($B11="","",SUMIFS('Sales Log'!$I$7:$I$3006,'Sales Log'!$C$7:$C$3006,$B11,'Sales Log'!$B$7:$B$3006,">="&cfg_Start,'Sales Log'!$B$7:$B$3006,"<="&cfg_End,'Sales Log'!$N$7:$N$3006,"OK")) | X11: =IF($B11="","",SUMIFS('Sales Log'!$L$7:$L$3006,'Sales Log'!$C$7:$C$3006,$B11,'Sales Log'!$B$7:$B$3006,">="&cfg_Start,'Sales Log'!$B$7:$B$3006,"<="&cfg_End,'Sales Log'!$N$7:$N$3006,"OK")) | Y11: =IF($B11="","",IF(SUM($V$7:$V$56)=0,0,$V11/SUM($V$7:$V$56))) | Z11: =IF($B11="",-1,N($V11)+ROW()/1000000) | AA11: =IF($B11="",-1E+15,N($X11)+ROW()/1000000)
D12: =IF($B12="","",SUMIFS('Recipe Builder'!$J$7:$J$406,'Recipe Builder'!$B$7:$B$406,$B12)) | F12: =IF($B12="","",IF(ISNUMBER($E12),$E12,N($D12))) | I12: =IF($B12="","",N($H12)/60*cfg_LaborRate) | K12: =IF($B12="","",$F12+N($G12)+$I12+N($J12)) | M12: =IF($B12="","",IF(AND(ISNUMBER($L12),$L12<0.95),MAX(0,$L12),cfg_TargetMargin)) | N12: =IF($B12="","",IF(cfg_Round>0,CEILING($K12/(1-$M12),cfg_Round),ROUND($K12/(1-$M12),2))) | P12: =IF(OR($B12="",N($O12)<=0),"",$O12-$K12) | Q12: =IF(OR($B12="",N($O12)<=0),"",$P12/$O12) | R12: =IF(OR($B12="",N($O12)<=0,N($K12)<=0),"",$P12/$K12) | S12: =IF(OR($B12="",N($O12)<=0),"",$F12/$O12) | T12: =IF($B12="","",IF(COUNTIF($B$7:$B$56,$B12)>1,"Duplicate name",IF(N($O12)<=0,"Set a price",IF(N($K12)<=0,"Add costs",IF($P12<0,"LOSS",IF($Q12<$M12-0.00001,"Below target",IF($S12>cfg_FoodCostTarget,"High food cost","Healthy"))))))) | U12: =IF($T12="","",IF($T12="Duplicate name","Each menu item needs a unique name",IF($T12="Set a price","Suggested starting price: "&cfg_Symbol&TEXT($N12,"0.00"),IF($T12="Add costs","Build the recipe or type an ingredient cost override",IF($T12="LOSS","Losing "&cfg_Symbol&TEXT(-$P12,"0.00")&" per sale - raise to "&cfg_Symbol&TEXT($N12,"0.00"),IF($T12="Below target","Raise to "&cfg_Symbol&TEXT($N12,"0.00")&" for a "&TEXT($M12,"0%")&" margin",IF($T12="High food cost","Margin OK; food cost "&TEXT($S12,"0%")&" is above "&TEXT(cfg_FoodCostTarget,"0%")&" target","On target"))))))) | V12: =IF($B12="","",SUMIFS('Sales Log'!$D$7:$D$3006,'Sales Log'!$C$7:$C$3006,$B12,'Sales Log'!$B$7:$B$3006,">="&cfg_Start,'Sales Log'!$B$7:$B$3006,"<="&cfg_End,'Sales Log'!$N$7:$N$3006,"OK")) | W12: =IF($B12="","",SUMIFS('Sales Log'!$I$7:$I$3006,'Sales Log'!$C$7:$C$3006,$B12,'Sales Log'!$B$7:$B$3006,">="&cfg_Start,'Sales Log'!$B$7:$B$3006,"<="&cfg_End,'Sales Log'!$N$7:$N$3006,"OK")) | X12: =IF($B12="","",SUMIFS('Sales Log'!$L$7:$L$3006,'Sales Log'!$C$7:$C$3006,$B12,'Sales Log'!$B$7:$B$3006,">="&cfg_Start,'Sales Log'!$B$7:$B$3006,"<="&cfg_End,'Sales Log'!$N$7:$N$3006,"OK")) | Y12: =IF($B12="","",IF(SUM($V$7:$V$56)=0,0,$V12/SUM($V$7:$V$56))) | Z12: =IF($B12="",-1,N($V12)+ROW()/1000000) | AA12: =IF($B12="",-1E+15,N($X12)+ROW()/1000000)
D13: =IF($B13="","",SUMIFS('Recipe Builder'!$J$7:$J$406,'Recipe Builder'!$B$7:$B$406,$B13)) | F13: =IF($B13="","",IF(ISNUMBER($E13),$E13,N($D13))) | I13: =IF($B13="","",N($H13)/60*cfg_LaborRate) | K13: =IF($B13="","",$F13+N($G13)+$I13+N($J13)) | M13: =IF($B13="","",IF(AND(ISNUMBER($L13),$L13<0.95),MAX(0,$L13),cfg_TargetMargin)) | N13: =IF($B13="","",IF(cfg_Round>0,CEILING($K13/(1-$M13),cfg_Round),ROUND($K13/(1-$M13),2))) | P13: =IF(OR($B13="",N($O13)<=0),"",$O13-$K13) | Q13: =IF(OR($B13="",N($O13)<=0),"",$P13/$O13) | R13: =IF(OR($B13="",N($O13)<=0,N($K13)<=0),"",$P13/$K13) | S13: =IF(OR($B13="",N($O13)<=0),"",$F13/$O13) | T13: =IF($B13="","",IF(COUNTIF($B$7:$B$56,$B13)>1,"Duplicate name",IF(N($O13)<=0,"Set a price",IF(N($K13)<=0,"Add costs",IF($P13<0,"LOSS",IF($Q13<$M13-0.00001,"Below target",IF($S13>cfg_FoodCostTarget,"High food cost","Healthy"))))))) | U13: =IF($T13="","",IF($T13="Duplicate name","Each menu item needs a unique name",IF($T13="Set a price","Suggested starting price: "&cfg_Symbol&TEXT($N13,"0.00"),IF($T13="Add costs","Build the recipe or type an ingredient cost override",IF($T13="LOSS","Losing "&cfg_Symbol&TEXT(-$P13,"0.00")&" per sale - raise to "&cfg_Symbol&TEXT($N13,"0.00"),IF($T13="Below target","Raise to "&cfg_Symbol&TEXT($N13,"0.00")&" for a "&TEXT($M13,"0%")&" margin",IF($T13="High food cost","Margin OK; food cost "&TEXT($S13,"0%")&" is above "&TEXT(cfg_FoodCostTarget,"0%")&" target","On target"))))))) | V13: =IF($B13="","",SUMIFS('Sales Log'!$D$7:$D$3006,'Sales Log'!$C$7:$C$3006,$B13,'Sales Log'!$B$7:$B$3006,">="&cfg_Start,'Sales Log'!$B$7:$B$3006,"<="&cfg_End,'Sales Log'!$N$7:$N$3006,"OK")) | W13: =IF($B13="","",SUMIFS('Sales Log'!$I$7:$I$3006,'Sales Log'!$C$7:$C$3006,$B13,'Sales Log'!$B$7:$B$3006,">="&cfg_Start,'Sales Log'!$B$7:$B$3006,"<="&cfg_End,'Sales Log'!$N$7:$N$3006,"OK")) | X13: =IF($B13="","",SUMIFS('Sales Log'!$L$7:$L$3006,'Sales Log'!$C$7:$C$3006,$B13,'Sales Log'!$B$7:$B$3006,">="&cfg_Start,'Sales Log'!$B$7:$B$3006,"<="&cfg_End,'Sales Log'!$N$7:$N$3006,"OK")) | Y13: =IF($B13="","",IF(SUM($V$7:$V$56)=0,0,$V13/SUM($V$7:$V$56))) | Z13: =IF($B13="",-1,N($V13)+ROW()/1000000) | AA13: =IF($B13="",-1E+15,N($X13)+ROW()/1000000)
D14: =IF($B14="","",SUMIFS('Recipe Builder'!$J$7:$J$406,'Recipe Builder'!$B$7:$B$406,$B14)) | F14: =IF($B14="","",IF(ISNUMBER($E14),$E14,N($D14))) | I14: =IF($B14="","",N($H14)/60*cfg_LaborRate) | K14: =IF($B14="","",$F14+N($G14)+$I14+N($J14)) | M14: =IF($B14="","",IF(AND(ISNUMBER($L14),$L14<0.95),MAX(0,$L14),cfg_TargetMargin)) | N14: =IF($B14="","",IF(cfg_Round>0,CEILING($K14/(1-$M14),cfg_Round),ROUND($K14/(1-$M14),2))) | P14: =IF(OR($B14="",N($O14)<=0),"",$O14-$K14) | Q14: =IF(OR($B14="",N($O14)<=0),"",$P14/$O14) | R14: =IF(OR($B14="",N($O14)<=0,N($K14)<=0),"",$P14/$K14) | S14: =IF(OR($B14="",N($O14)<=0),"",$F14/$O14) | T14: =IF($B14="","",IF(COUNTIF($B$7:$B$56,$B14)>1,"Duplicate name",IF(N($O14)<=0,"Set a price",IF(N($K14)<=0,"Add costs",IF($P14<0,"LOSS",IF($Q14<$M14-0.00001,"Below target",IF($S14>cfg_FoodCostTarget,"High food cost","Healthy"))))))) | U14: =IF($T14="","",IF($T14="Duplicate name","Each menu item needs a unique name",IF($T14="Set a price","Suggested starting price: "&cfg_Symbol&TEXT($N14,"0.00"),IF($T14="Add costs","Build the recipe or type an ingredient cost override",IF($T14="LOSS","Losing "&cfg_Symbol&TEXT(-$P14,"0.00")&" per sale - raise to "&cfg_Symbol&TEXT($N14,"0.00"),IF($T14="Below target","Raise to "&cfg_Symbol&TEXT($N14,"0.00")&" for a "&TEXT($M14,"0%")&" margin",IF($T14="High food cost","Margin OK; food cost "&TEXT($S14,"0%")&" is above "&TEXT(cfg_FoodCostTarget,"0%")&" target","On target"))))))) | V14: =IF($B14="","",SUMIFS('Sales Log'!$D$7:$D$3006,'Sales Log'!$C$7:$C$3006,$B14,'Sales Log'!$B$7:$B$3006,">="&cfg_Start,'Sales Log'!$B$7:$B$3006,"<="&cfg_End,'Sales Log'!$N$7:$N$3006,"OK")) | W14: =IF($B14="","",SUMIFS('Sales Log'!$I$7:$I$3006,'Sales Log'!$C$7:$C$3006,$B14,'Sales Log'!$B$7:$B$3006,">="&cfg_Start,'Sales Log'!$B$7:$B$3006,"<="&cfg_End,'Sales Log'!$N$7:$N$3006,"OK")) | X14: =IF($B14="","",SUMIFS('Sales Log'!$L$7:$L$3006,'Sales Log'!$C$7:$C$3006,$B14,'Sales Log'!$B$7:$B$3006,">="&cfg_Start,'Sales Log'!$B$7:$B$3006,"<="&cfg_End,'Sales Log'!$N$7:$N$3006,"OK")) | Y14: =IF($B14="","",IF(SUM($V$7:$V$56)=0,0,$V14/SUM($V$7:$V$56))) | Z14: =IF($B14="",-1,N($V14)+ROW()/1000000) | AA14: =IF($B14="",-1E+15,N($X14)+ROW()/1000000)
D15: =IF($B15="","",SUMIFS('Recipe Builder'!$J$7:$J$406,'Recipe Builder'!$B$7:$B$406,$B15)) | F15: =IF($B15="","",IF(ISNUMBER($E15),$E15,N($D15))) | I15: =IF($B15="","",N($H15)/60*cfg_LaborRate) | K15: =IF($B15="","",$F15+N($G15)+$I15+N($J15)) | M15: =IF($B15="","",IF(AND(ISNUMBER($L15),$L15<0.95),MAX(0,$L15),cfg_TargetMargin)) | N15: =IF($B15="","",IF(cfg_Round>0,CEILING($K15/(1-$M15),cfg_Round),ROUND($K15/(1-$M15),2))) | P15: =IF(OR($B15="",N($O15)<=0),"",$O15-$K15) | Q15: =IF(OR($B15="",N($O15)<=0),"",$P15/$O15) | R15: =IF(OR($B15="",N($O15)<=0,N($K15)<=0),"",$P15/$K15) | S15: =IF(OR($B15="",N($O15)<=0),"",$F15/$O15) | T15: =IF($B15="","",IF(COUNTIF($B$7:$B$56,$B15)>1,"Duplicate name",IF(N($O15)<=0,"Set a price",IF(N($K15)<=0,"Add costs",IF($P15<0,"LOSS",IF($Q15<$M15-0.00001,"Below target",IF($S15>cfg_FoodCostTarget,"High food cost","Healthy"))))))) | U15: =IF($T15="","",IF($T15="Duplicate name","Each menu item needs a unique name",IF($T15="Set a price","Suggested starting price: "&cfg_Symbol&TEXT($N15,"0.00"),IF($T15="Add costs","Build the recipe or type an ingredient cost override",IF($T15="LOSS","Losing "&cfg_Symbol&TEXT(-$P15,"0.00")&" per sale - raise to "&cfg_Symbol&TEXT($N15,"0.00"),IF($T15="Below target","Raise to "&cfg_Symbol&TEXT($N15,"0.00")&" for a "&TEXT($M15,"0%")&" margin",IF($T15="High food cost","Margin OK; food cost "&TEXT($S15,"0%")&" is above "&TEXT(cfg_FoodCostTarget,"0%")&" target","On target"))))))) | V15: =IF($B15="","",SUMIFS('Sales Log'!$D$7:$D$3006,'Sales Log'!$C$7:$C$3006,$B15,'Sales Log'!$B$7:$B$3006,">="&cfg_Start,'Sales Log'!$B$7:$B$3006,"<="&cfg_End,'Sales Log'!$N$7:$N$3006,"OK")) | W15: =IF($B15="","",SUMIFS('Sales Log'!$I$7:$I$3006,'Sales Log'!$C$7:$C$3006,$B15,'Sales Log'!$B$7:$B$3006,">="&cfg_Start,'Sales Log'!$B$7:$B$3006,"<="&cfg_End,'Sales Log'!$N$7:$N$3006,"OK")) | X15: =IF($B15="","",SUMIFS('Sales Log'!$L$7:$L$3006,'Sales Log'!$C$7:$C$3006,$B15,'Sales Log'!$B$7:$B$3006,">="&cfg_Start,'Sales Log'!$B$7:$B$3006,"<="&cfg_End,'Sales Log'!$N$7:$N$3006,"OK")) | Y15: =IF($B15="","",IF(SUM($V$7:$V$56)=0,0,$V15/SUM($V$7:$V$56))) | Z15: =IF($B15="",-1,N($V15)+ROW()/1000000) | AA15: =IF($B15="",-1E+15,N($X15)+ROW()/1000000)
D16: =IF($B16="","",SUMIFS('Recipe Builder'!$J$7:$J$406,'Recipe Builder'!$B$7:$B$406,$B16)) | F16: =IF($B16="","",IF(ISNUMBER($E16),$E16,N($D16))) | I16: =IF($B16="","",N($H16)/60*cfg_LaborRate) | K16: =IF($B16="","",$F16+N($G16)+$I16+N($J16)) | M16: =IF($B16="","",IF(AND(ISNUMBER($L16),$L16<0.95),MAX(0,$L16),cfg_TargetMargin)) | N16: =IF($B16="","",IF(cfg_Round>0,CEILING($K16/(1-$M16),cfg_Round),ROUND($K16/(1-$M16),2))) | P16: =IF(OR($B16="",N($O16)<=0),"",$O16-$K16) | Q16: =IF(OR($B16="",N($O16)<=0),"",$P16/$O16) | R16: =IF(OR($B16="",N($O16)<=0,N($K16)<=0),"",$P16/$K16) | S16: =IF(OR($B16="",N($O16)<=0),"",$F16/$O16) | T16: =IF($B16="","",IF(COUNTIF($B$7:$B$56,$B16)>1,"Duplicate name",IF(N($O16)<=0,"Set a price",IF(N($K16)<=0,"Add costs",IF($P16<0,"LOSS",IF($Q16<$M16-0.00001,"Below target",IF($S16>cfg_FoodCostTarget,"High food cost","Healthy"))))))) | U16: =IF($T16="","",IF($T16="Duplicate name","Each menu item needs a unique name",IF($T16="Set a price","Suggested starting price: "&cfg_Symbol&TEXT($N16,"0.00"),IF($T16="Add costs","Build the recipe or type an ingredient cost override",IF($T16="LOSS","Losing "&cfg_Symbol&TEXT(-$P16,"0.00")&" per sale - raise to "&cfg_Symbol&TEXT($N16,"0.00"),IF($T16="Below target","Raise to "&cfg_Symbol&TEXT($N16,"0.00")&" for a "&TEXT($M16,"0%")&" margin",IF($T16="High food cost","Margin OK; food cost "&TEXT($S16,"0%")&" is above "&TEXT(cfg_FoodCostTarget,"0%")&" target","On target"))))))) | V16: =IF($B16="","",SUMIFS('Sales Log'!$D$7:$D$3006,'Sales Log'!$C$7:$C$3006,$B16,'Sales Log'!$B$7:$B$3006,">="&cfg_Start,'Sales Log'!$B$7:$B$3006,"<="&cfg_End,'Sales Log'!$N$7:$N$3006,"OK")) | W16: =IF($B16="","",SUMIFS('Sales Log'!$I$7:$I$3006,'Sales Log'!$C$7:$C$3006,$B16,'Sales Log'!$B$7:$B$3006,">="&cfg_Start,'Sales Log'!$B$7:$B$3006,"<="&cfg_End,'Sales Log'!$N$7:$N$3006,"OK")) | X16: =IF($B16="","",SUMIFS('Sales Log'!$L$7:$L$3006,'Sales Log'!$C$7:$C$3006,$B16,'Sales Log'!$B$7:$B$3006,">="&cfg_Start,'Sales Log'!$B$7:$B$3006,"<="&cfg_End,'Sales Log'!$N$7:$N$3006,"OK")) | Y16: =IF($B16="","",IF(SUM($V$7:$V$56)=0,0,$V16/SUM($V$7:$V$56))) | Z16: =IF($B16="",-1,N($V16)+ROW()/1000000) | AA16: =IF($B16="",-1E+15,N($X16)+ROW()/1000000)
D17: =IF($B17="","",SUMIFS('Recipe Builder'!$J$7:$J$406,'Recipe Builder'!$B$7:$B$406,$B17)) | F17: =IF($B17="","",IF(ISNUMBER($E17),$E17,N($D17))) | I17: =IF($B17="","",N($H17)/60*cfg_LaborRate) | K17: =IF($B17="","",$F17+N($G17)+$I17+N($J17)) | M17: =IF($B17="","",IF(AND(ISNUMBER($L17),$L17<0.95),MAX(0,$L17),cfg_TargetMargin)) | N17: =IF($B17="","",IF(cfg_Round>0,CEILING($K17/(1-$M17),cfg_Round),ROUND($K17/(1-$M17),2))) | P17: =IF(OR($B17="",N($O17)<=0),"",$O17-$K17) | Q17: =IF(OR($B17="",N($O17)<=0),"",$P17/$O17) | R17: =IF(OR($B17="",N($O17)<=0,N($K17)<=0),"",$P17/$K17) | S17: =IF(OR($B17="",N($O17)<=0),"",$F17/$O17) | T17: =IF($B17="","",IF(COUNTIF($B$7:$B$56,$B17)>1,"Duplicate name",IF(N($O17)<=0,"Set a price",IF(N($K17)<=0,"Add costs",IF($P17<0,"LOSS",IF($Q17<$M17-0.00001,"Below target",IF($S17>cfg_FoodCostTarget,"High food cost","Healthy"))))))) | U17: =IF($T17="","",IF($T17="Duplicate name","Each menu item needs a unique name",IF($T17="Set a price","Suggested starting price: "&cfg_Symbol&TEXT($N17,"0.00"),IF($T17="Add costs","Build the recipe or type an ingredient cost override",IF($T17="LOSS","Losing "&cfg_Symbol&TEXT(-$P17,"0.00")&" per sale - raise to "&cfg_Symbol&TEXT($N17,"0.00"),IF($T17="Below target","Raise to "&cfg_Symbol&TEXT($N17,"0.00")&" for a "&TEXT($M17,"0%")&" margin",IF($T17="High food cost","Margin OK; food cost "&TEXT($S17,"0%")&" is above "&TEXT(cfg_FoodCostTarget,"0%")&" target","On target"))))))) | V17: =IF($B17="","",SUMIFS('Sales Log'!$D$7:$D$3006,'Sales Log'!$C$7:$C$3006,$B17,'Sales Log'!$B$7:$B$3006,">="&cfg_Start,'Sales Log'!$B$7:$B$3006,"<="&cfg_End,'Sales Log'!$N$7:$N$3006,"OK")) | W17: =IF($B17="","",SUMIFS('Sales Log'!$I$7:$I$3006,'Sales Log'!$C$7:$C$3006,$B17,'Sales Log'!$B$7:$B$3006,">="&cfg_Start,'Sales Log'!$B$7:$B$3006,"<="&cfg_End,'Sales Log'!$N$7:$N$3006,"OK")) | X17: =IF($B17="","",SUMIFS('Sales Log'!$L$7:$L$3006,'Sales Log'!$C$7:$C$3006,$B17,'Sales Log'!$B$7:$B$3006,">="&cfg_Start,'Sales Log'!$B$7:$B$3006,"<="&cfg_End,'Sales Log'!$N$7:$N$3006,"OK")) | Y17: =IF($B17="","",IF(SUM($V$7:$V$56)=0,0,$V17/SUM($V$7:$V$56))) | Z17: =IF($B17="",-1,N($V17)+ROW()/1000000) | AA17: =IF($B17="",-1E+15,N($X17)+ROW()/1000000)
D18: =IF($B18="","",SUMIFS('Recipe Builder'!$J$7:$J$406,'Recipe Builder'!$B$7:$B$406,$B18)) | F18: =IF($B18="","",IF(ISNUMBER($E18),$E18,N($D18))) | I18: =IF($B18="","",N($H18)/60*cfg_LaborRate) | K18: =IF($B18="","",$F18+N($G18)+$I18+N($J18)) | M18: =IF($B18="","",IF(AND(ISNUMBER($L18),$L18<0.95),MAX(0,$L18),cfg_TargetMargin)) | N18: =IF($B18="","",IF(cfg_Round>0,CEILING($K18/(1-$M18),cfg_Round),ROUND($K18/(1-$M18),2))) | P18: =IF(OR($B18="",N($O18)<=0),"",$O18-$K18) | Q18: =IF(OR($B18="",N($O18)<=0),"",$P18/$O18) | R18: =IF(OR($B18="",N($O18)<=0,N($K18)<=0),"",$P18/$K18) | S18: =IF(OR($B18="",N($O18)<=0),"",$F18/$O18) | T18: =IF($B18="","",IF(COUNTIF($B$7:$B$56,$B18)>1,"Duplicate name",IF(N($O18)<=0,"Set a price",IF(N($K18)<=0,"Add costs",IF($P18<0,"LOSS",IF($Q18<$M18-0.00001,"Below target",IF($S18>cfg_FoodCostTarget,"High food cost","Healthy"))))))) | U18: =IF($T18="","",IF($T18="Duplicate name","Each menu item needs a unique name",IF($T18="Set a price","Suggested starting price: "&cfg_Symbol&TEXT($N18,"0.00"),IF($T18="Add costs","Build the recipe or type an ingredient cost override",IF($T18="LOSS","Losing "&cfg_Symbol&TEXT(-$P18,"0.00")&" per sale - raise to "&cfg_Symbol&TEXT($N18,"0.00"),IF($T18="Below target","Raise to "&cfg_Symbol&TEXT($N18,"0.00")&" for a "&TEXT($M18,"0%")&" margin",IF($T18="High food cost","Margin OK; food cost "&TEXT($S18,"0%")&" is above "&TEXT(cfg_FoodCostTarget,"0%")&" target","On target"))))))) | V18: =IF($B18="","",SUMIFS('Sales Log'!$D$7:$D$3006,'Sales Log'!$C$7:$C$3006,$B18,'Sales Log'!$B$7:$B$3006,">="&cfg_Start,'Sales Log'!$B$7:$B$3006,"<="&cfg_End,'Sales Log'!$N$7:$N$3006,"OK")) | W18: =IF($B18="","",SUMIFS('Sales Log'!$I$7:$I$3006,'Sales Log'!$C$7:$C$3006,$B18,'Sales Log'!$B$7:$B$3006,">="&cfg_Start,'Sales Log'!$B$7:$B$3006,"<="&cfg_End,'Sales Log'!$N$7:$N$3006,"OK")) | X18: =IF($B18="","",SUMIFS('Sales Log'!$L$7:$L$3006,'Sales Log'!$C$7:$C$3006,$B18,'Sales Log'!$B$7:$B$3006,">="&cfg_Start,'Sales Log'!$B$7:$B$3006,"<="&cfg_End,'Sales Log'!$N$7:$N$3006,"OK")) | Y18: =IF($B18="","",IF(SUM($V$7:$V$56)=0,0,$V18/SUM($V$7:$V$56))) | Z18: =IF($B18="",-1,N($V18)+ROW()/1000000) | AA18: =IF($B18="",-1E+15,N($X18)+ROW()/1000000)
... D56: =IF($B56="","",SUMIFS('Recipe Builder'!$J$7:$J$406,'Recipe Builder'!$B$7:$B$406,$B56)) | F56: =IF($B56="","",IF(ISNUMBER($E56),$E56,N($D56))) | I56: =IF($B56="","",N($H56)/60*cfg_LaborRate) | K56: =IF($B56="","",$F56+N($G56)+$I56+N($J56)) | M56: =IF($B56="","",IF(AND(ISNUMBER($L56),$L56<0.95),MAX(0,$L56),cfg_TargetMargin)) | N56: =IF($B56="","",IF(cfg_Round>0,CEILING($K56/(1-$M56),cfg_Round),ROUND($K56/(1-$M56),2))) | P56: =IF(OR($B56="",N($O56)<=0),"",$O56-$K56) | Q56: =IF(OR($B56="",N($O56)<=0),"",$P56/$O56) | R56: =IF(OR($B56="",N($O56)<=0,N($K56)<=0),"",$P56/$K56) | S56: =IF(OR($B56="",N($O56)<=0),"",$F56/$O56) | T56: =IF($B56="","",IF(COUNTIF($B$7:$B$56,$B56)>1,"Duplicate name",IF(N($O56)<=0,"Set a price",IF(N($K56)<=0,"Add costs",IF($P56<0,"LOSS",IF($Q56<$M56-0.00001,"Below target",IF($S56>cfg_FoodCostTarget,"High food cost","Healthy"))))))) | U56: =IF($T56="","",IF($T56="Duplicate name","Each menu item needs a unique name",IF($T56="Set a price","Suggested starting price: "&cfg_Symbol&TEXT($N56,"0.00"),IF($T56="Add costs","Build the recipe or type an ingredient cost override",IF($T56="LOSS","Losing "&cfg_Symbol&TEXT(-$P56,"0.00")&" per sale - raise to "&cfg_Symbol&TEXT($N56,"0.00"),IF($T56="Below target","Raise to "&cfg_Symbol&TEXT($N56,"0.00")&" for a "&TEXT($M56,"0%")&" margin",IF($T56="High food cost","Margin OK; food cost "&TEXT($S56,"0%")&" is above "&TEXT(cfg_FoodCostTarget,"0%")&" target","On target"))))))) | V56: =IF($B56="","",SUMIFS('Sales Log'!$D$7:$D$3006,'Sales Log'!$C$7:$C$3006,$B56,'Sales Log'!$B$7:$B$3006,">="&cfg_Start,'Sales Log'!$B$7:$B$3006,"<="&cfg_End,'Sales Log'!$N$7:$N$3006,"OK")) | W56: =IF($B56="","",SUMIFS('Sales Log'!$I$7:$I$3006,'Sales Log'!$C$7:$C$3006,$B56,'Sales Log'!$B$7:$B$3006,">="&cfg_Start,'Sales Log'!$B$7:$B$3006,"<="&cfg_End,'Sales Log'!$N$7:$N$3006,"OK")) | X56: =IF($B56="","",SUMIFS('Sales Log'!$L$7:$L$3006,'Sales Log'!$C$7:$C$3006,$B56,'Sales Log'!$B$7:$B$3006,">="&cfg_Start,'Sales Log'!$B$7:$B$3006,"<="&cfg_End,'Sales Log'!$N$7:$N$3006,"OK")) | Y56: =IF($B56="","",IF(SUM($V$7:$V$56)=0,0,$V56/SUM($V$7:$V$56))) | Z56: =IF($B56="",-1,N($V56)+ROW()/1000000) | AA56: =IF($B56="",-1E+15,N($X56)+ROW()/1000000)
B57: TOTAL / ALERTS | T57: =COUNTIF(T7:T56,"LOSS")+COUNTIF(T7:T56,"Below target")&" need attention" | V57: =SUM(V7:V56) | W57: =SUM(W7:W56) | X57: =SUM(X7:X56)
B59: MARGIN = profit / price. MARKUP = profit / cost. Example: cost 4.00, price 10.00 -> margin 60%, markup 150%. Suggested price = total cost / (1 - target margin), rounded UP. Prep labour here is a pricing allowance only - real wages are recorded in Expenses. Gross profit in the sales columns uses ingredients + packaging + other variable cost (no labour), so labour is never counted twice.

Sheet Recipe Builder
B2: Recipe Builder | L2: NoviraNest
B3: One row per ingredient per menu item. Quantities convert automatically to each ingredient's stock unit. Incompatible units are flagged and never costed.
B4: › Start Here | C4: › Dashboard | D4: › Menu Pricing | F4: › Inventory
B5: WHAT GOES INTO ONE SERVING | F5: AUTOMATIC COSTING & USAGE
B6: Menu item | C6: Ingredient | D6: Qty per serving | E6: Unit | F6: Stock unit | G6: Unit check | H6: Qty in stock units | I6: ="Cost per stock unit ("&cfg_Symbol&")" | J6: ="Line cost ("&cfg_Symbol&")" | K6: Items sold since count | L6: Usage since count
F7: =IF($C7="","",IFERROR(INDEX('Inventory'!$D$7:$D$106,MATCH($C7,'Inventory'!$B$7:$B$106,0))&"","?")) | G7: =IF(AND($B7="",$C7=""),"",IF($B7="","Pick menu item",IF(ISNA(MATCH($B7,'Menu Pricing'!$B$7:$B$56,0)),"Not on Menu Pricing",IF($C7="","Pick ingredient",IF($F7="?","Not in Inventory",IF($F7="","Set stock unit in Inventory",IF(N($D7)<=0,"Enter quantity",IF($E7="","Pick unit",IF(IFERROR(INDEX('Lists'!$C$6:$C$30,MATCH($E7,'Lists'!$B$6:$B$30,0)),"?")<>IFERROR(INDEX('Lists'!$C$6:$C$30,MATCH($F7,'Lists'!$B$6:$B$30,0)),"?"),"Unit mismatch",IF(ISNUMBER(INDEX('Inventory'!$G$7:$G$106,MATCH($C7,'Inventory'!$B$7:$B$106,0))),"OK","Add price in Inventory")))))))))) | H7: =IF($G7<>"OK","",$D7*INDEX('Lists'!$D$6:$D$30,MATCH($E7,'Lists'!$B$6:$B$30,0))/INDEX('Lists'!$D$6:$D$30,MATCH($F7,'Lists'!$B$6:$B$30,0))) | I7: =IF($G7<>"OK","",INDEX('Inventory'!$G$7:$G$106,MATCH($C7,'Inventory'!$B$7:$B$106,0))) | J7: =IF($G7<>"OK","",$H7*$I7) | K7: =IF($G7<>"OK","",SUMIFS('Sales Log'!$D$7:$D$3006,'Sales Log'!$C$7:$C$3006,$B7,'Sales Log'!$B$7:$B$3006,">="&cfg_CountDate,'Sales Log'!$N$7:$N$3006,"OK")) | L7: =IF($G7<>"OK","",$H7*$K7)
F8: =IF($C8="","",IFERROR(INDEX('Inventory'!$D$7:$D$106,MATCH($C8,'Inventory'!$B$7:$B$106,0))&"","?")) | G8: =IF(AND($B8="",$C8=""),"",IF($B8="","Pick menu item",IF(ISNA(MATCH($B8,'Menu Pricing'!$B$7:$B$56,0)),"Not on Menu Pricing",IF($C8="","Pick ingredient",IF($F8="?","Not in Inventory",IF($F8="","Set stock unit in Inventory",IF(N($D8)<=0,"Enter quantity",IF($E8="","Pick unit",IF(IFERROR(INDEX('Lists'!$C$6:$C$30,MATCH($E8,'Lists'!$B$6:$B$30,0)),"?")<>IFERROR(INDEX('Lists'!$C$6:$C$30,MATCH($F8,'Lists'!$B$6:$B$30,0)),"?"),"Unit mismatch",IF(ISNUMBER(INDEX('Inventory'!$G$7:$G$106,MATCH($C8,'Inventory'!$B$7:$B$106,0))),"OK","Add price in Inventory")))))))))) | H8: =IF($G8<>"OK","",$D8*INDEX('Lists'!$D$6:$D$30,MATCH($E8,'Lists'!$B$6:$B$30,0))/INDEX('Lists'!$D$6:$D$30,MATCH($F8,'Lists'!$B$6:$B$30,0))) | I8: =IF($G8<>"OK","",INDEX('Inventory'!$G$7:$G$106,MATCH($C8,'Inventory'!$B$7:$B$106,0))) | J8: =IF($G8<>"OK","",$H8*$I8) | K8: =IF($G8<>"OK","",SUMIFS('Sales Log'!$D$7:$D$3006,'Sales Log'!$C$7:$C$3006,$B8,'Sales Log'!$B$7:$B$3006,">="&cfg_CountDate,'Sales Log'!$N$7:$N$3006,"OK")) | L8: =IF($G8<>"OK","",$H8*$K8)
F9: =IF($C9="","",IFERROR(INDEX('Inventory'!$D$7:$D$106,MATCH($C9,'Inventory'!$B$7:$B$106,0))&"","?")) | G9: =IF(AND($B9="",$C9=""),"",IF($B9="","Pick menu item",IF(ISNA(MATCH($B9,'Menu Pricing'!$B$7:$B$56,0)),"Not on Menu Pricing",IF($C9="","Pick ingredient",IF($F9="?","Not in Inventory",IF($F9="","Set stock unit in Inventory",IF(N($D9)<=0,"Enter quantity",IF($E9="","Pick unit",IF(IFERROR(INDEX('Lists'!$C$6:$C$30,MATCH($E9,'Lists'!$B$6:$B$30,0)),"?")<>IFERROR(INDEX('Lists'!$C$6:$C$30,MATCH($F9,'Lists'!$B$6:$B$30,0)),"?"),"Unit mismatch",IF(ISNUMBER(INDEX('Inventory'!$G$7:$G$106,MATCH($C9,'Inventory'!$B$7:$B$106,0))),"OK","Add price in Inventory")))))))))) | H9: =IF($G9<>"OK","",$D9*INDEX('Lists'!$D$6:$D$30,MATCH($E9,'Lists'!$B$6:$B$30,0))/INDEX('Lists'!$D$6:$D$30,MATCH($F9,'Lists'!$B$6:$B$30,0))) | I9: =IF($G9<>"OK","",INDEX('Inventory'!$G$7:$G$106,MATCH($C9,'Inventory'!$B$7:$B$106,0))) | J9: =IF($G9<>"OK","",$H9*$I9) | K9: =IF($G9<>"OK","",SUMIFS('Sales Log'!$D$7:$D$3006,'Sales Log'!$C$7:$C$3006,$B9,'Sales Log'!$B$7:$B$3006,">="&cfg_CountDate,'Sales Log'!$N$7:$N$3006,"OK")) | L9: =IF($G9<>"OK","",$H9*$K9)
F10: =IF($C10="","",IFERROR(INDEX('Inventory'!$D$7:$D$106,MATCH($C10,'Inventory'!$B$7:$B$106,0))&"","?")) | G10: =IF(AND($B10="",$C10=""),"",IF($B10="","Pick menu item",IF(ISNA(MATCH($B10,'Menu Pricing'!$B$7:$B$56,0)),"Not on Menu Pricing",IF($C10="","Pick ingredient",IF($F10="?","Not in Inventory",IF($F10="","Set stock unit in Inventory",IF(N($D10)<=0,"Enter quantity",IF($E10="","Pick unit",IF(IFERROR(INDEX('Lists'!$C$6:$C$30,MATCH($E10,'Lists'!$B$6:$B$30,0)),"?")<>IFERROR(INDEX('Lists'!$C$6:$C$30,MATCH($F10,'Lists'!$B$6:$B$30,0)),"?"),"Unit mismatch",IF(ISNUMBER(INDEX('Inventory'!$G$7:$G$106,MATCH($C10,'Inventory'!$B$7:$B$106,0))),"OK","Add price in Inventory")))))))))) | H10: =IF($G10<>"OK","",$D10*INDEX('Lists'!$D$6:$D$30,MATCH($E10,'Lists'!$B$6:$B$30,0))/INDEX('Lists'!$D$6:$D$30,MATCH($F10,'Lists'!$B$6:$B$30,0))) | I10: =IF($G10<>"OK","",INDEX('Inventory'!$G$7:$G$106,MATCH($C10,'Inventory'!$B$7:$B$106,0))) | J10: =IF($G10<>"OK","",$H10*$I10) | K10: =IF($G10<>"OK","",SUMIFS('Sales Log'!$D$7:$D$3006,'Sales Log'!$C$7:$C$3006,$B10,'Sales Log'!$B$7:$B$3006,">="&cfg_CountDate,'Sales Log'!$N$7:$N$3006,"OK")) | L10: =IF($G10<>"OK","",$H10*$K10)
F11: =IF($C11="","",IFERROR(INDEX('Inventory'!$D$7:$D$106,MATCH($C11,'Inventory'!$B$7:$B$106,0))&"","?")) | G11: =IF(AND($B11="",$C11=""),"",IF($B11="","Pick menu item",IF(ISNA(MATCH($B11,'Menu Pricing'!$B$7:$B$56,0)),"Not on Menu Pricing",IF($C11="","Pick ingredient",IF($F11="?","Not in Inventory",IF($F11="","Set stock unit in Inventory",IF(N($D11)<=0,"Enter quantity",IF($E11="","Pick unit",IF(IFERROR(INDEX('Lists'!$C$6:$C$30,MATCH($E11,'Lists'!$B$6:$B$30,0)),"?")<>IFERROR(INDEX('Lists'!$C$6:$C$30,MATCH($F11,'Lists'!$B$6:$B$30,0)),"?"),"Unit mismatch",IF(ISNUMBER(INDEX('Inventory'!$G$7:$G$106,MATCH($C11,'Inventory'!$B$7:$B$106,0))),"OK","Add price in Inventory")))))))))) | H11: =IF($G11<>"OK","",$D11*INDEX('Lists'!$D$6:$D$30,MATCH($E11,'Lists'!$B$6:$B$30,0))/INDEX('Lists'!$D$6:$D$30,MATCH($F11,'Lists'!$B$6:$B$30,0))) | I11: =IF($G11<>"OK","",INDEX('Inventory'!$G$7:$G$106,MATCH($C11,'Inventory'!$B$7:$B$106,0))) | J11: =IF($G11<>"OK","",$H11*$I11) | K11: =IF($G11<>"OK","",SUMIFS('Sales Log'!$D$7:$D$3006,'Sales Log'!$C$7:$C$3006,$B11,'Sales Log'!$B$7:$B$3006,">="&cfg_CountDate,'Sales Log'!$N$7:$N$3006,"OK")) | L11: =IF($G11<>"OK","",$H11*$K11)
F12: =IF($C12="","",IFERROR(INDEX('Inventory'!$D$7:$D$106,MATCH($C12,'Inventory'!$B$7:$B$106,0))&"","?")) | G12: =IF(AND($B12="",$C12=""),"",IF($B12="","Pick menu item",IF(ISNA(MATCH($B12,'Menu Pricing'!$B$7:$B$56,0)),"Not on Menu Pricing",IF($C12="","Pick ingredient",IF($F12="?","Not in Inventory",IF($F12="","Set stock unit in Inventory",IF(N($D12)<=0,"Enter quantity",IF($E12="","Pick unit",IF(IFERROR(INDEX('Lists'!$C$6:$C$30,MATCH($E12,'Lists'!$B$6:$B$30,0)),"?")<>IFERROR(INDEX('Lists'!$C$6:$C$30,MATCH($F12,'Lists'!$B$6:$B$30,0)),"?"),"Unit mismatch",IF(ISNUMBER(INDEX('Inventory'!$G$7:$G$106,MATCH($C12,'Inventory'!$B$7:$B$106,0))),"OK","Add price in Inventory")))))))))) | H12: =IF($G12<>"OK","",$D12*INDEX('Lists'!$D$6:$D$30,MATCH($E12,'Lists'!$B$6:$B$30,0))/INDEX('Lists'!$D$6:$D$30,MATCH($F12,'Lists'!$B$6:$B$30,0))) | I12: =IF($G12<>"OK","",INDEX('Inventory'!$G$7:$G$106,MATCH($C12,'Inventory'!$B$7:$B$106,0))) | J12: =IF($G12<>"OK","",$H12*$I12) | K12: =IF($G12<>"OK","",SUMIFS('Sales Log'!$D$7:$D$3006,'Sales Log'!$C$7:$C$3006,$B12,'Sales Log'!$B$7:$B$3006,">="&cfg_CountDate,'Sales Log'!$N$7:$N$3006,"OK")) | L12: =IF($G12<>"OK","",$H12*$K12)
F13: =IF($C13="","",IFERROR(INDEX('Inventory'!$D$7:$D$106,MATCH($C13,'Inventory'!$B$7:$B$106,0))&"","?")) | G13: =IF(AND($B13="",$C13=""),"",IF($B13="","Pick menu item",IF(ISNA(MATCH($B13,'Menu Pricing'!$B$7:$B$56,0)),"Not on Menu Pricing",IF($C13="","Pick ingredient",IF($F13="?","Not in Inventory",IF($F13="","Set stock unit in Inventory",IF(N($D13)<=0,"Enter quantity",IF($E13="","Pick unit",IF(IFERROR(INDEX('Lists'!$C$6:$C$30,MATCH($E13,'Lists'!$B$6:$B$30,0)),"?")<>IFERROR(INDEX('Lists'!$C$6:$C$30,MATCH($F13,'Lists'!$B$6:$B$30,0)),"?"),"Unit mismatch",IF(ISNUMBER(INDEX('Inventory'!$G$7:$G$106,MATCH($C13,'Inventory'!$B$7:$B$106,0))),"OK","Add price in Inventory")))))))))) | H13: =IF($G13<>"OK","",$D13*INDEX('Lists'!$D$6:$D$30,MATCH($E13,'Lists'!$B$6:$B$30,0))/INDEX('Lists'!$D$6:$D$30,MATCH($F13,'Lists'!$B$6:$B$30,0))) | I13: =IF($G13<>"OK","",INDEX('Inventory'!$G$7:$G$106,MATCH($C13,'Inventory'!$B$7:$B$106,0))) | J13: =IF($G13<>"OK","",$H13*$I13) | K13: =IF($G13<>"OK","",SUMIFS('Sales Log'!$D$7:$D$3006,'Sales Log'!$C$7:$C$3006,$B13,'Sales Log'!$B$7:$B$3006,">="&cfg_CountDate,'Sales Log'!$N$7:$N$3006,"OK")) | L13: =IF($G13<>"OK","",$H13*$K13)
